Workbook

Sheet Resumen
A1: Análisis completo de implementación Fixed y operación RET
A2: Planeación mensual vs. horas OpenAir | Capacidad neta: lun-jue 8,5 h, viernes 8 h y festivos Colombia | Corte 2026-09-04
A4: Fixed esperado h | D4: Fixed real h (planeados) | G4: RET esperado h | J4: RET real h (planeados)
A5: =SUMIFS(Cumplimiento!$H$5:$H$106,Cumplimiento!$Z$5:$Z$106,"No") -> 9501.95 | D5: =SUMIFS(Cumplimiento!$I$5:$I$106,Cumplimiento!$Z$5:$Z$106,"No") -> 7397.9 | G5: =SUMIFS(Cumplimiento!$L$5:$L$106,Cumplimiento!$Z$5:$Z$106,"No") -> 505.35 | J5: =SUMIFS(Cumplimiento!$M$5:$M$106,Cumplimiento!$Z$5:$Z$106,"No") -> 210.85
A8: Total esperado h | D8: Total real h (planeados) | G8: Desviación total h | J8: Persona-mes por revisar
A9: =SUMIFS(Cumplimiento!$P$5:$P$106,Cumplimiento!$Z$5:$Z$106,"No") -> 10007.3 | D9: =SUMIFS(Cumplimiento!$Q$5:$Q$106,Cumplimiento!$Z$5:$Z$106,"No") -> 7608.75 | G9: =SUMIFS(Cumplimiento!$R$5:$R$106,Cumplimiento!$Z$5:$Z$106,"No") -> -2398.55 | J9: =COUNTIF(Cumplimiento!$Y$5:$Y$106,"Revisar*")+COUNTIF(Cumplimiento!$Y$5:$Y$106,"Desviación total") -> 59
A13: Mes | B13: Fixed esperado | C13: Fixed real | D13: Desv. Fixed | E13: RET esperado | F13: RET real | G13: Desv. RET | H13: Total esperado | I13: Total real | J13: Desv. total
A14: Julio | B14: =SUMIFS(Cumplimiento!$H$5:$H$106,Cumplimiento!$C$5:$C$106,A14,Cumplimiento!$Z$5:$Z$106,"No") -> 5104 | C14: =SUMIFS(Cumplimiento!$I$5:$I$106,Cumplimiento!$C$5:$C$106,A14,Cumplimiento!$Z$5:$Z$106,"No") -> 4033.75 | D14: =C14-B14 -> -1070.25 | E14: =SUMIFS(Cumplimiento!$L$5:$L$106,Cumplimiento!$C$5:$C$106,A14,Cumplimiento!$Z$5:$Z$106,"No") -> 0 | F14: =SUMIFS(Cumplimiento!$M$5:$M$106,Cumplimiento!$C$5:$C$106,A14,Cumplimiento!$Z$5:$Z$106,"No") -> 0 | G14: =F14-E14 -> 0 | H14: =B14+E14 -> 5104 | I14: =C14+F14 -> 4033.75 | J14: =I14-H14 -> -1070.25
A15: Agosto | B15: =SUMIFS(Cumplimiento!$H$5:$H$106,Cumplimiento!$C$5:$C$106,A15,Cumplimiento!$Z$5:$Z$106,"No") -> 3872 | C15: =SUMIFS(Cumplimiento!$I$5:$I$106,Cumplimiento!$C$5:$C$106,A15,Cumplimiento!$Z$5:$Z$106,"No") -> 3059.8 | D15: =C15-B15 -> -812.2 | E15: =SUMIFS(Cumplimiento!$L$5:$L$106,Cumplimiento!$C$5:$C$106,A15,Cumplimiento!$Z$5:$Z$106,"No") -> 368 | F15: =SUMIFS(Cumplimiento!$M$5:$M$106,Cumplimiento!$C$5:$C$106,A15,Cumplimiento!$Z$5:$Z$106,"No") -> 165.4 | G15: =F15-E15 -> -202.6 | H15: =B15+E15 -> 4240 | I15: =C15+F15 -> 3225.2 | J15: =I15-H15 -> -1014.8
A16: Septiembre | B16: =SUMIFS(Cumplimiento!$H$5:$H$106,Cumplimiento!$C$5:$C$106,A16,Cumplimiento!$Z$5:$Z$106,"No") -> 525.95 | C16: =SUMIFS(Cumplimiento!$I$5:$I$106,Cumplimiento!$C$5:$C$106,A16,Cumplimiento!$Z$5:$Z$106,"No") -> 304.35 | D16: =C16-B16 -> -221.6 | E16: =SUMIFS(Cumplimiento!$L$5:$L$106,Cumplimiento!$C$5:$C$106,A16,Cumplimiento!$Z$5:$Z$106,"No") -> 137.35 | F16: =SUMIFS(Cumplimiento!$M$5:$M$106,Cumplimiento!$C$5:$C$106,A16,Cumplimiento!$Z$5:$Z$106,"No") -> 45.45 | G16: =F16-E16 -> -91.9 | H16: =B16+E16 -> 663.3 | I16: =C16+F16 -> 349.8 | J16: =I16-H16 -> -313.5
A18: Lectura ejecutiva
A19: ="• Fixed: "&ROUND(D5,2)&" h reales frente a "&ROUND(A5,2)&" h esperadas; desviación "&ROUND(D5-A5,2)&" h." -> • Fixed: 7397,9 h reales frente a 9501,95 h esperadas; desviación -2104,05 h.
A20: ="• RET: "&ROUND(J5,2)&" h reales frente a "&ROUND(G5,2)&" h esperadas; desviación "&ROUND(J5-G5,2)&" h." -> • RET: 210,85 h reales frente a 505,35 h esperadas; desviación -294,5 h.
A21: ="• Alertas Fixed: "&COUNTIFS(Cumplimiento!$W$5:$W$106,"<>En rango Fixed",Cumplimiento!$W$5:$W$106,"<>No aplica Fixed",Cumplimiento!$W$5:$W$106,"<>Excluido")&" persona-mes." -> • Alertas Fixed: 58 persona-mes.
A22: ="• Alertas RET: "&COUNTIFS(Cumplimiento!$X$5:$X$106,"<>En rango RET",Cumplimiento!$X$5:$X$106,"<>No aplica RET",Cumplimiento!$X$5:$X$106,"<>Excluido")&" persona-mes." -> • Alertas RET: 20 persona-mes.
A23: ="• Cargas no planeadas RET: "&COUNTIF(Cumplimiento!$X$5:$X$106,"Carga no planeada RET")&"; meses sin horas RET pese a estar planeadas: "&COUNTIF(Cumplimiento!$X$5:$X$106,"Sin horas RET")&"." -> • Cargas no planeadas RET: 2; meses sin horas RET pese a estar planeadas: 15.
A24: • Las personas de auditoría/contratistas permanecen excluidas de alertas de ausencia. La capacidad no asignada se muestra explícitamente cuando Fixed + RET es menor de 100%.
A25: ="• La fuente RET contiene "&ROUND(SUMIFS('RET OpenAir fuente'!$D$5:$D$320,'RET OpenAir fuente'!$F$5:$F$320,"Sí"),2)&" h en el período; "&ROUND(J5,2)&" h corresponden a personas incluidas en esta planeación." -> • La fuente RET contiene 452,85 h en el período; 210,85 h corresponden a personas incluidas en esta planeación.
A26: ="• La fuente Fixed contiene "&ROUND(D5+SUMIFS(Anomalias!$F$5:$F$200,Anomalias!$B$5:$B$200,"Persona no planeada"),2)&" h en el período; "&ROUND(D5,2)&" h corresponden a personas incluidas en esta planeación." -> • La fuente Fixed contiene 8853,9 h en el período; 7397,9 h corresponden a personas incluidas en esta planeación.

Sheet Cumplimiento
A1: Cumplimiento integral Fixed y RET
A2: Horas esperadas = capacidad neta x porcentaje planeado. Se analizan volumen, cumplimiento y mezcla de ambas líneas. Corte: 2026-09-04.
A4: Equipo | B4: Persona | C4: Mes | D4: % Fixed plan | E4: % RET plan | F4: % no asignado | G4: Capacidad h | H4: Fixed esperado h | I4: Fixed real h | J4: Desv. Fixed h | K4: Cumpl. Fixed | L4: RET esperado h | M4: RET real h | N4: Desv. RET h | O4: Cumpl. RET | P4: Total esperado h | Q4: Total real h | R4: Desv. total h | S4: % Fixed real | T4: % RET real | U4: Desv. Fixed pp | V4: Desv. RET pp | W4: Estado Fixed | X4: Estado RET | Y4: Estado ambas líneas | Z4: Excluido
A5: Los Dioses | B5: Gerson Nicolas Pineda Lara | C5: Julio | D5: 1 | E5: 0 | F5: =MAX(0,1-D5-E5) -> 0 | G5: 176 | H5: =D5*G5 -> 176 | I5: 135.5 | J5: =I5-H5 -> -40.5 | K5: =IF(H5=0,"",I5/H5) -> 0.76988636 | L5: =E5*G5 -> 0 | M5: 0 | N5: =M5-L5 -> 0 | O5: =IF(L5=0,"",M5/L5) | P5: =H5+L5 -> 176 | Q5: =I5+M5 -> 135.5 | R5: =Q5-P5 -> -40.5 | S5: =IF(Q5=0,"",I5/Q5) -> 1 | T5: =IF(Q5=0,"",M5/Q5) -> 0 | U5: =IF(S5="","",S5-D5) -> 0 | V5: =IF(T5="","",T5-E5) -> 0 | W5: =IF(Z5="Sí","Excluido",IF(AND(D5=0,I5=0),"No aplica Fixed",IF(AND(D5=0,I5>0),"Carga no planeada Fixed",IF(AND(D5>0,I5=0),"Sin horas Fixed",IF(ABS(J5)>MAX(8,H5*10%),"Desviación Fixed","En rango Fixed"))))) -> Desviación Fixed | X5: =IF(Z5="Sí","Excluido",IF(AND(E5=0,M5=0),"No aplica RET",IF(AND(E5=0,M5>0),"Carga no planeada RET",IF(AND(E5>0,M5=0),"Sin horas RET",IF(ABS(N5)>MAX(8,L5*10%),"Desviación RET","En rango RET"))))) -> No aplica RET | Y5: =IF(Z5="Sí","Excluido - auditoría/contratista",IF(OR(ISNUMBER(SEARCH("Carga",W5)),ISNUMBER(SEARCH("Sin horas",W5)),ISNUMBER(SEARCH("Desviación",W5)),ISNUMBER(SEARCH("Carga",X5)),ISNUMBER(SEARCH("Sin horas",X5)),ISNUMBER(SEARCH("Desviación",X5))),"Revisar ambas líneas",IF(ABS(R5)>MAX(8,P5*10%),"Desviación total",IF(F5>0,"En rango - plan parcial","En rango ambas líneas")))) -> Revisar ambas líneas | Z5: No
A6: Los Dioses | B6: Gerson Nicolas Pineda Lara | C6: Agosto | D6: 0.9 | E6: 0.1 | F6: =MAX(0,1-D6-E6) -> 0 | G6: 160 | H6: =D6*G6 -> 144 | I6: 162.9 | J6: =I6-H6 -> 18.9 | K6: =IF(H6=0,"",I6/H6) -> 1.13125 | L6: =E6*G6 -> 16 | M6: 14.1 | N6: =M6-L6 -> -1.9 | O6: =IF(L6=0,"",M6/L6) -> 0.88125 | P6: =H6+L6 -> 160 | Q6: =I6+M6 -> 177 | R6: =Q6-P6 -> 17 | S6: =IF(Q6=0,"",I6/Q6) -> 0.92033898 | T6: =IF(Q6=0,"",M6/Q6) -> 0.079661017 | U6: =IF(S6="","",S6-D6) -> 0.020338983 | V6: =IF(T6="","",T6-E6) -> -0.020338983 | W6: =IF(Z6="Sí","Excluido",IF(AND(D6=0,I6=0),"No aplica Fixed",IF(AND(D6=0,I6>0),"Carga no planeada Fixed",IF(AND(D6>0,I6=0),"Sin horas Fixed",IF(ABS(J6)>MAX(8,H6*10%),"Desviación Fixed","En rango Fixed"))))) -> Desviación Fixed | X6: =IF(Z6="Sí","Excluido",IF(AND(E6=0,M6=0),"No aplica RET",IF(AND(E6=0,M6>0),"Carga no planeada RET",IF(AND(E6>0,M6=0),"Sin horas RET",IF(ABS(N6)>MAX(8,L6*10%),"Desviación RET","En rango RET"))))) -> En rango RET | Y6: =IF(Z6="Sí","Excluido - auditoría/contratista",IF(OR(ISNUMBER(SEARCH("Carga",W6)),ISNUMBER(SEARCH("Sin horas",W6)),ISNUMBER(SEARCH("Desviación",W6)),ISNUMBER(SEARCH("Carga",X6)),ISNUMBER(SEARCH("Sin horas",X6)),ISNUMBER(SEARCH("Desviación",X6))),"Revisar ambas líneas",IF(ABS(R6)>MAX(8,P6*10%),"Desviación total",IF(F6>0,"En rango - plan parcial","En rango ambas líneas")))) -> Revisar ambas líneas | Z6: No
A7: Los Dioses | B7: Gerson Nicolas Pineda Lara | C7: Septiembre | D7: 0.9 | E7: 0.1 | F7: =MAX(0,1-D7-E7) -> 0 | G7: 33.5 | H7: =D7*G7 -> 30.15 | I7: 31.05 | J7: =I7-H7 -> 0.9 | K7: =IF(H7=0,"",I7/H7) -> 1.0298507 | L7: =E7*G7 -> 3.35 | M7: 3.45 | N7: =M7-L7 -> 0.1 | O7: =IF(L7=0,"",M7/L7) -> 1.0298507 | P7: =H7+L7 -> 33.5 | Q7: =I7+M7 -> 34.5 | R7: =Q7-P7 -> 1 | S7: =IF(Q7=0,"",I7/Q7) -> 0.9 | T7: =IF(Q7=0,"",M7/Q7) -> 0.1 | U7: =IF(S7="","",S7-D7) -> 0 | V7: =IF(T7="","",T7-E7) -> 0 | W7: =IF(Z7="Sí","Excluido",IF(AND(D7=0,I7=0),"No aplica Fixed",IF(AND(D7=0,I7>0),"Carga no planeada Fixed",IF(AND(D7>0,I7=0),"Sin horas Fixed",IF(ABS(J7)>MAX(8,H7*10%),"Desviación Fixed","En rango Fixed"))))) -> En rango Fixed | X7: =IF(Z7="Sí","Excluido",IF(AND(E7=0,M7=0),"No aplica RET",IF(AND(E7=0,M7>0),"Carga no planeada RET",IF(AND(E7>0,M7=0),"Sin horas RET",IF(ABS(N7)>MAX(8,L7*10%),"Desviación RET","En rango RET"))))) -> En rango RET | Y7: =IF(Z7="Sí","Excluido - auditoría/contratista",IF(OR(ISNUMBER(SEARCH("Carga",W7)),ISNUMBER(SEARCH("Sin horas",W7)),ISNUMBER(SEARCH("Desviación",W7)),ISNUMBER(SEARCH("Carga",X7)),ISNUMBER(SEARCH("Sin horas",X7)),ISNUMBER(SEARCH("Desviación",X7))),"Revisar ambas líneas",IF(ABS(R7)>MAX(8,P7*10%),"Desviación total",IF(F7>0,"En rango - plan parcial","En rango ambas líneas")))) -> En rango ambas líneas | Z7: No
A8: Los Dioses | B8: Diego Andres Saavedra Perez | C8: Julio | D8: 1 | E8: 0 | F8: =MAX(0,1-D8-E8) -> 0 | G8: 176 | H8: =D8*G8 -> 176 | I8: 184.5 | J8: =I8-H8 -> 8.5 | K8: =IF(H8=0,"",I8/H8) -> 1.0482955 | L8: =E8*G8 -> 0 | M8: 0 | N8: =M8-L8 -> 0 | O8: =IF(L8=0,"",M8/L8) | P8: =H8+L8 -> 176 | Q8: =I8+M8 -> 184.5 | R8: =Q8-P8 -> 8.5 | S8: =IF(Q8=0,"",I8/Q8) -> 1 | T8: =IF(Q8=0,"",M8/Q8) -> 0 | U8: =IF(S8="","",S8-D8) -> 0 | V8: =IF(T8="","",T8-E8) -> 0 | W8: =IF(Z8="Sí","Excluido",IF(AND(D8=0,I8=0),"No aplica Fixed",IF(AND(D8=0,I8>0),"Carga no planeada Fixed",IF(AND(D8>0,I8=0),"Sin horas Fixed",IF(ABS(J8)>MAX(8,H8*10%),"Desviación Fixed","En rango Fixed"))))) -> En rango Fixed | X8: =IF(Z8="Sí","Excluido",IF(AND(E8=0,M8=0),"No aplica RET",IF(AND(E8=0,M8>0),"Carga no planeada RET",IF(AND(E8>0,M8=0),"Sin horas RET",IF(ABS(N8)>MAX(8,L8*10%),"Desviación RET","En rango RET"))))) -> No aplica RET | Y8: =IF(Z8="Sí","Excluido - auditoría/contratista",IF(OR(ISNUMBER(SEARCH("Carga",W8)),ISNUMBER(SEARCH("Sin horas",W8)),ISNUMBER(SEARCH("Desviación",W8)),ISNUMBER(SEARCH("Carga",X8)),ISNUMBER(SEARCH("Sin horas",X8)),ISNUMBER(SEARCH("Desviación",X8))),"Revisar ambas líneas",IF(ABS(R8)>MAX(8,P8*10%),"Desviación total",IF(F8>0,"En rango - plan parcial","En rango ambas líneas")))) -> En rango ambas líneas | Z8: No
A9: Los Dioses | B9: Diego Andres Saavedra Perez | C9: Agosto | D9: 0.9 | E9: 0.1 | F9: =MAX(0,1-D9-E9) -> 0 | G9: 160 | H9: =D9*G9 -> 144 | I9: 69.5 | J9: =I9-H9 -> -74.5 | K9: =IF(H9=0,"",I9/H9) -> 0.48263889 | L9: =E9*G9 -> 16 | M9: 0 | N9: =M9-L9 -> -16 | O9: =IF(L9=0,"",M9/L9) -> 0 | P9: =H9+L9 -> 160 | Q9: =I9+M9 -> 69.5 | R9: =Q9-P9 -> -90.5 | S9: =IF(Q9=0,"",I9/Q9) -> 1 | T9: =IF(Q9=0,"",M9/Q9) -> 0 | U9: =IF(S9="","",S9-D9) -> 0.1 | V9: =IF(T9="","",T9-E9) -> -0.1 | W9: =IF(Z9="Sí","Excluido",IF(AND(D9=0,I9=0),"No aplica Fixed",IF(AND(D9=0,I9>0),"Carga no planeada Fixed",IF(AND(D9>0,I9=0),"Sin horas Fixed",IF(ABS(J9)>MAX(8,H9*10%),"Desviación Fixed","En rango Fixed"))))) -> Desviación Fixed | X9: =IF(Z9="Sí","Excluido",IF(AND(E9=0,M9=0),"No aplica RET",IF(AND(E9=0,M9>0),"Carga no planeada RET",IF(AND(E9>0,M9=0),"Sin horas RET",IF(ABS(N9)>MAX(8,L9*10%),"Desviación RET","En rango RET"))))) -> Sin horas RET | Y9: =IF(Z9="Sí","Excluido - auditoría/contratista",IF(OR(ISNUMBER(SEARCH("Carga",W9)),ISNUMBER(SEARCH("Sin horas",W9)),ISNUMBER(SEARCH("Desviación",W9)),ISNUMBER(SEARCH("Carga",X9)),ISNUMBER(SEARCH("Sin horas",X9)),ISNUMBER(SEARCH("Desviación",X9))),"Revisar ambas líneas",IF(ABS(R9)>MAX(8,P9*10%),"Desviación total",IF(F9>0,"En rango - plan parcial","En rango ambas líneas")))) -> Revisar ambas líneas | Z9: No
A10: Los Dioses | B10: Diego Andres Saavedra Perez | C10: Septiembre | D10: 0.9 | E10: 0.1 | F10: =MAX(0,1-D10-E10) -> 0 | G10: 33.5 | H10: =D10*G10 -> 30.15 | I10: 0 | J10: =I10-H10 -> -30.15 | K10: =IF(H10=0,"",I10/H10) -> 0 | L10: =E10*G10 -> 3.35 | M10: 0 | N10: =M10-L10 -> -3.35 | O10: =IF(L10=0,"",M10/L10) -> 0 | P10: =H10+L10 -> 33.5 | Q10: =I10+M10 -> 0 | R10: =Q10-P10 -> -33.5 | S10: =IF(Q10=0,"",I10/Q10) | T10: =IF(Q10=0,"",M10/Q10) | U10: =IF(S10="","",S10-D10) | V10: =IF(T10="","",T10-E10) | W10: =IF(Z10="Sí","Excluido",IF(AND(D10=0,I10=0),"No aplica Fixed",IF(AND(D10=0,I10>0),"Carga no planeada Fixed",IF(AND(D10>0,I10=0),"Sin horas Fixed",IF(ABS(J10)>MAX(8,H10*10%),"Desviación Fixed","En rango Fixed"))))) -> Sin horas Fixed | X10: =IF(Z10="Sí","Excluido",IF(AND(E10=0,M10=0),"No aplica RET",IF(AND(E10=0,M10>0),"Carga no planeada RET",IF(AND(E10>0,M10=0),"Sin horas RET",IF(ABS(N10)>MAX(8,L10*10%),"Desviación RET","En rango RET"))))) -> Sin horas RET | Y10: =IF(Z10="Sí","Excluido - auditoría/contratista",IF(OR(ISNUMBER(SEARCH("Carga",W10)),ISNUMBER(SEARCH("Sin horas",W10)),ISNUMBER(SEARCH("Desviación",W10)),ISNUMBER(SEARCH("Carga",X10)),ISNUMBER(SEARCH("Sin horas",X10)),ISNUMBER(SEARCH("Desviación",X10))),"Revisar ambas líneas",IF(ABS(R10)>MAX(8,P10*10%),"Desviación total",IF(F10>0,"En rango - plan parcial","En rango ambas líneas")))) -> Revisar ambas líneas | Z10: No
A11: Los Dioses | B11: Harold Abdullah Lamphrey Munoz | C11: Julio | D11: 1 | E11: 0 | F11: =MAX(0,1-D11-E11) -> 0 | G11: 176 | H11: =D11*G11 -> 176 | I11: 180 | J11: =I11-H11 -> 4 | K11: =IF(H11=0,"",I11/H11) -> 1.0227273 | L11: =E11*G11 -> 0 | M11: 0 | N11: =M11-L11 -> 0 | O11: =IF(L11=0,"",M11/L11) | P11: =H11+L11 -> 176 | Q11: =I11+M11 -> 180 | R11: =Q11-P11 -> 4 | S11: =IF(Q11=0,"",I11/Q11) -> 1 | T11: =IF(Q11=0,"",M11/Q11) -> 0 | U11: =IF(S11="","",S11-D11) -> 0 | V11: =IF(T11="","",T11-E11) -> 0 | W11: =IF(Z11="Sí","Excluido",IF(AND(D11=0,I11=0),"No aplica Fixed",IF(AND(D11=0,I11>0),"Carga no planeada Fixed",IF(AND(D11>0,I11=0),"Sin horas Fixed",IF(ABS(J11)>MAX(8,H11*10%),"Desviación Fixed","En rango Fixed"))))) -> En rango Fixed | X11: =IF(Z11="Sí","Excluido",IF(AND(E11=0,M11=0),"No aplica RET",IF(AND(E11=0,M11>0),"Carga no planeada RET",IF(AND(E11>0,M11=0),"Sin horas RET",IF(ABS(N11)>MAX(8,L11*10%),"Desviación RET","En rango RET"))))) -> No aplica RET | Y11: =IF(Z11="Sí","Excluido - auditoría/contratista",IF(OR(ISNUMBER(SEARCH("Carga",W11)),ISNUMBER(SEARCH("Sin horas",W11)),ISNUMBER(SEARCH("Desviación",W11)),ISNUMBER(SEARCH("Carga",X11)),ISNUMBER(SEARCH("Sin horas",X11)),ISNUMBER(SEARCH("Desviación",X11))),"Revisar ambas líneas",IF(ABS(R11)>MAX(8,P11*10%),"Desviación total",IF(F11>0,"En rango - plan parcial","En rango ambas líneas")))) -> En rango ambas líneas | Z11: No
A12: Los Dioses | B12: Harold Abdullah Lamphrey Munoz | C12: Agosto | D12: 1 | E12: 0 | F12: =MAX(0,1-D12-E12) -> 0 | G12: 160 | H12: =D12*G12 -> 160 | I12: 88.5 | J12: =I12-H12 -> -71.5 | K12: =IF(H12=0,"",I12/H12) -> 0.553125 | L12: =E12*G12 -> 0 | M12: 0 | N12: =M12-L12 -> 0 | O12: =IF(L12=0,"",M12/L12) | P12: =H12+L12 -> 160 | Q12: =I12+M12 -> 88.5 | R12: =Q12-P12 -> -71.5 | S12: =IF(Q12=0,"",I12/Q12) -> 1 | T12: =IF(Q12=0,"",M12/Q12) -> 0 | U12: =IF(S12="","",S12-D12) -> 0 | V12: =IF(T12="","",T12-E12) -> 0 | W12: =IF(Z12="Sí","Excluido",IF(AND(D12=0,I12=0),"No aplica Fixed",IF(AND(D12=0,I12>0),"Carga no planeada Fixed",IF(AND(D12>0,I12=0),"Sin horas Fixed",IF(ABS(J12)>MAX(8,H12*10%),"Desviación Fixed","En rango Fixed"))))) -> Desviación Fixed | X12: =IF(Z12="Sí","Excluido",IF(AND(E12=0,M12=0),"No aplica RET",IF(AND(E12=0,M12>0),"Carga no planeada RET",IF(AND(E12>0,M12=0),"Sin horas RET",IF(ABS(N12)>MAX(8,L12*10%),"Desviación RET","En rango RET"))))) -> No aplica RET | Y12: =IF(Z12="Sí","Excluido - auditoría/contratista",IF(OR(ISNUMBER(SEARCH("Carga",W12)),ISNUMBER(SEARCH("Sin horas",W12)),ISNUMBER(SEARCH("Desviación",W12)),ISNUMBER(SEARCH("Carga",X12)),ISNUMBER(SEARCH("Sin horas",X12)),ISNUMBER(SEARCH("Desviación",X12))),"Revisar ambas líneas",IF(ABS(R12)>MAX(8,P12*10%),"Desviación total",IF(F12>0,"En rango - plan parcial","En rango ambas líneas")))) -> Revisar ambas líneas | Z12: No
A13: Los Dioses | B13: Harold Abdullah Lamphrey Munoz | C13: Septiembre | D13: 1 | E13: 0 | F13: =MAX(0,1-D13-E13) -> 0 | G13: 33.5 | H13: =D13*G13 -> 33.5 | I13: 0 | J13: =I13-H13 -> -33.5 | K13: =IF(H13=0,"",I13/H13) -> 0 | L13: =E13*G13 -> 0 | M13: 0 | N13: =M13-L13 -> 0 | O13: =IF(L13=0,"",M13/L13) | P13: =H13+L13 -> 33.5 | Q13: =I13+M13 -> 0 | R13: =Q13-P13 -> -33.5 | S13: =IF(Q13=0,"",I13/Q13) | T13: =IF(Q13=0,"",M13/Q13) | U13: =IF(S13="","",S13-D13) | V13: =IF(T13="","",T13-E13) | W13: =IF(Z13="Sí","Excluido",IF(AND(D13=0,I13=0),"No aplica Fixed",IF(AND(D13=0,I13>0),"Carga no planeada Fixed",IF(AND(D13>0,I13=0),"Sin horas Fixed",IF(ABS(J13)>MAX(8,H13*10%),"Desviación Fixed","En rango Fixed"))))) -> Sin horas Fixed | X13: =IF(Z13="Sí","Excluido",IF(AND(E13=0,M13=0),"No aplica RET",IF(AND(E13=0,M13>0),"Carga no planeada RET",IF(AND(E13>0,M13=0),"Sin horas RET",IF(ABS(N13)>MAX(8,L13*10%),"Desviación RET","En rango RET"))))) -> No aplica RET | Y13: =IF(Z13="Sí","Excluido - auditoría/contratista",IF(OR(ISNUMBER(SEARCH("Carga",W13)),ISNUMBER(SEARCH("Sin horas",W13)),ISNUMBER(SEARCH("Desviación",W13)),ISNUMBER(SEARCH("Carga",X13)),ISNUMBER(SEARCH("Sin horas",X13)),ISNUMBER(SEARCH("Desviación",X13))),"Revisar ambas líneas",IF(ABS(R13)>MAX(8,P13*10%),"Desviación total",IF(F13>0,"En rango - plan parcial","En rango ambas líneas")))) -> Revisar ambas líneas | Z13: No
A14: Anomalias | B14: Diana Patricia Aldana Moreno | C14: Julio | D14: 1 | E14: 0 | F14: =MAX(0,1-D14-E14) -> 0 | G14: 176 | H14: =D14*G14 -> 176 | I14: 179.5 | J14: =I14-H14 -> 3.5 | K14: =IF(H14=0,"",I14/H14) -> 1.0198864 | L14: =E14*G14 -> 0 | M14: 0 | N14: =M14-L14 -> 0 | O14: =IF(L14=0,"",M14/L14) | P14: =H14+L14 -> 176 | Q14: =I14+M14 -> 179.5 | R14: =Q14-P14 -> 3.5 | S14: =IF(Q14=0,"",I14/Q14) -> 1 | T14: =IF(Q14=0,"",M14/Q14) -> 0 | U14: =IF(S14="","",S14-D14) -> 0 | V14: =IF(T14="","",T14-E14) -> 0 | W14: =IF(Z14="Sí","Excluido",IF(AND(D14=0,I14=0),"No aplica Fixed",IF(AND(D14=0,I14>0),"Carga no planeada Fixed",IF(AND(D14>0,I14=0),"Sin horas Fixed",IF(ABS(J14)>MAX(8,H14*10%),"Desviación Fixed","En rango Fixed"))))) -> En rango Fixed | X14: =IF(Z14="Sí","Excluido",IF(AND(E14=0,M14=0),"No aplica RET",IF(AND(E14=0,M14>0),"Carga no planeada RET",IF(AND(E14>0,M14=0),"Sin horas RET",IF(ABS(N14)>MAX(8,L14*10%),"Desviación RET","En rango RET"))))) -> No aplica RET | Y14: =IF(Z14="Sí","Excluido - auditoría/contratista",IF(OR(ISNUMBER(SEARCH("Carga",W14)),ISNUMBER(SEARCH("Sin horas",W14)),ISNUMBER(SEARCH("Desviación",W14)),ISNUMBER(SEARCH("Carga",X14)),ISNUMBER(SEARCH("Sin horas",X14)),ISNUMBER(SEARCH("Desviación",X14))),"Revisar ambas líneas",IF(ABS(R14)>MAX(8,P14*10%),"Desviación total",IF(F14>0,"En rango - plan parcial","En rango ambas líneas")))) -> En rango ambas líneas | Z14: No
A15: Anomalias | B15: Diana Patricia Aldana Moreno | C15: Agosto | D15: 0.5 | E15: 0 | F15: =MAX(0,1-D15-E15) -> 0.5 | G15: 160 | H15: =D15*G15 -> 80 | I15: 157.5 | J15: =I15-H15 -> 77.5 | K15: =IF(H15=0,"",I15/H15) -> 1.96875 | L15: =E15*G15 -> 0 | M15: 0 | N15: =M15-L15 -> 0 | O15: =IF(L15=0,"",M15/L15) | P15: =H15+L15 -> 80 | Q15: =I15+M15 -> 157.5 | R15: =Q15-P15 -> 77.5 | S15: =IF(Q15=0,"",I15/Q15) -> 1 | T15: =IF(Q15=0,"",M15/Q15) -> 0 | U15: =IF(S15="","",S15-D15) -> 0.5 | V15: =IF(T15="","",T15-E15) -> 0 | W15: =IF(Z15="Sí","Excluido",IF(AND(D15=0,I15=0),"No aplica Fixed",IF(AND(D15=0,I15>0),"Carga no planeada Fixed",IF(AND(D15>0,I15=0),"Sin horas Fixed",IF(ABS(J15)>MAX(8,H15*10%),"Desviación Fixed","En rango Fixed"))))) -> Desviación Fixed | X15: =IF(Z15="Sí","Excluido",IF(AND(E15=0,M15=0),"No aplica RET",IF(AND(E15=0,M15>0),"Carga no planeada RET",IF(AND(E15>0,M15=0),"Sin horas RET",IF(ABS(N15)>MAX(8,L15*10%),"Desviación RET","En rango RET"))))) -> No aplica RET | Y15: =IF(Z15="Sí","Excluido - auditoría/contratista",IF(OR(ISNUMBER(SEARCH("Carga",W15)),ISNUMBER(SEARCH("Sin horas",W15)),ISNUMBER(SEARCH("Desviación",W15)),ISNUMBER(SEARCH("Carga",X15)),ISNUMBER(SEARCH("Sin horas",X15)),ISNUMBER(SEARCH("Desviación",X15))),"Revisar ambas líneas",IF(ABS(R15)>MAX(8,P15*10%),"Desviación total",IF(F15>0,"En rango - plan parcial","En rango ambas líneas")))) -> Revisar ambas líneas | Z15: No
A16: Anomalias | B16: Diana Patricia Aldana Moreno | C16: Septiembre | D16: 0 | E16: 0 | F16: =MAX(0,1-D16-E16) -> 1 | G16: 33.5 | H16: =D16*G16 -> 0 | I16: 0 | J16: =I16-H16 -> 0 | K16: =IF(H16=0,"",I16/H16) | L16: =E16*G16 -> 0 | M16: 0 | N16: =M16-L16 -> 0 | O16: =IF(L16=0,"",M16/L16) | P16: =H16+L16 -> 0 | Q16: =I16+M16 -> 0 | R16: =Q16-P16 -> 0 | S16: =IF(Q16=0,"",I16/Q16) | T16: =IF(Q16=0,"",M16/Q16) | U16: =IF(S16="","",S16-D16) | V16: =IF(T16="","",T16-E16) | W16: =IF(Z16="Sí","Excluido",IF(AND(D16=0,I16=0),"No aplica Fixed",IF(AND(D16=0,I16>0),"Carga no planeada Fixed",IF(AND(D16>0,I16=0),"Sin horas Fixed",IF(ABS(J16)>MAX(8,H16*10%),"Desviación Fixed","En rango Fixed"))))) -> No aplica Fixed | X16: =IF(Z16="Sí","Excluido",IF(AND(E16=0,M16=0),"No aplica RET",IF(AND(E16=0,M16>0),"Carga no planeada RET",IF(AND(E16>0,M16=0),"Sin horas RET",IF(ABS(N16)>MAX(8,L16*10%),"Desviación RET","En rango RET"))))) -> No aplica RET | Y16: =IF(Z16="Sí","Excluido - auditoría/contratista",IF(OR(ISNUMBER(SEARCH("Carga",W16)),ISNUMBER(SEARCH("Sin horas",W16)),ISNUMBER(SEARCH("Desviación",W16)),ISNUMBER(SEARCH("Carga",X16)),ISNUMBER(SEARCH("Sin horas",X16)),ISNUMBER(SEARCH("Desviación",X16))),"Revisar ambas líneas",IF(ABS(R16)>MAX(8,P16*10%),"Desviación total",IF(F16>0,"En rango - plan parcial","En rango ambas líneas")))) -> En rango - plan parcial | Z16: No
... A106: Contratistas | B106: Leonardo Beltran | C106: Septiembre | D106: 0 | E106: 0 | F106: =MAX(0,1-D106-E106) -> 1 | G106: 33.5 | H106: =D106*G106 -> 0 | I106: 0 | J106: =I106-H106 -> 0 | K106: =IF(H106=0,"",I106/H106) | L106: =E106*G106 -> 0 | M106: 0 | N106: =M106-L106 -> 0 | O106: =IF(L106=0,"",M106/L106) | P106: =H106+L106 -> 0 | Q106: =I106+M106 -> 0 | R106: =Q106-P106 -> 0 | S106: =IF(Q106=0,"",I106/Q106) | T106: =IF(Q106=0,"",M106/Q106) | U106: =IF(S106="","",S106-D106) | V106: =IF(T106="","",T106-E106) | W106: =IF(Z106="Sí","Excluido",IF(AND(D106=0,I106=0),"No aplica Fixed",IF(AND(D106=0,I106>0),"Carga no planeada Fixed",IF(AND(D106>0,I106=0),"Sin horas Fixed",IF(ABS(J106)>MAX(8,H106*10%),"Desviación Fixed","En rango Fixed"))))) -> Excluido | X106: =IF(Z106="Sí","Excluido",IF(AND(E106=0,M106=0),"No aplica RET",IF(AND(E106=0,M106>0),"Carga no planeada RET",IF(AND(E106>0,M106=0),"Sin horas RET",IF(ABS(N106)>MAX(8,L106*10%),"Desviación RET","En rango RET"))))) -> Excluido | Y106: =IF(Z106="Sí","Excluido - auditoría/contratista",IF(OR(ISNUMBER(SEARCH("Carga",W106)),ISNUMBER(SEARCH("Sin horas",W106)),ISNUMBER(SEARCH("Desviación",W106)),ISNUMBER(SEARCH("Carga",X106)),ISNUMBER(SEARCH("Sin horas",X106)),ISNUMBER(SEARCH("Desviación",X106))),"Revisar ambas líneas",IF(ABS(R106)>MAX(8,P106*10%),"Desviación total",IF(F106>0,"En rango - plan parcial","En rango ambas líneas")))) -> Excluido - auditoría/contratista | Z106: Sí

Sheet Anomalias
A1: Anomalías y controles
A2: Incluye anomalías del período y controles históricos del archivo completo cuando se indica.
A4: Ámbito | B4: Tipo | C4: Severidad | D4: Fecha/Mes | E4: Persona | F4: Valor | G4: Detalle | H4: Acción sugerida
A5: Posterior al corte | B5: Fecha futura | C5: Alta | D5: 2026-09-11 | E5: ZAMBRANO, JUAN | F5: 0.5 | G5: Carga Fixed después del corte 2026-09-04; excluida del cumplimiento. | H5: Validar si es carga anticipada o fecha errónea.
A6: Posterior al corte | B6: Fecha futura | C6: Alta | D6: 2026-09-10 | E6: ZAMBRANO, JUAN | F6: 0.5 | G6: Carga Fixed después del corte 2026-09-04; excluida del cumplimiento. | H6: Validar si es carga anticipada o fecha errónea.
A7: Posterior al corte | B7: Fecha futura | C7: Alta | D7: 2026-09-09 | E7: ZAMBRANO, JUAN | F7: 0.5 | G7: Carga Fixed después del corte 2026-09-04; excluida del cumplimiento. | H7: Validar si es carga anticipada o fecha errónea.
A8: Posterior al corte | B8: Fecha futura | C8: Alta | D8: 2026-09-08 | E8: ZAMBRANO, JUAN | F8: 0.5 | G8: Carga Fixed después del corte 2026-09-04; excluida del cumplimiento. | H8: Validar si es carga anticipada o fecha errónea.
A9: Posterior al corte | B9: Fecha futura | C9: Alta | D9: 2026-09-07 | E9: ZAMBRANO, JUAN | F9: 0.5 | G9: Carga Fixed después del corte 2026-09-04; excluida del cumplimiento. | H9: Validar si es carga anticipada o fecha errónea.
A10: Jul-Sep 4 | B10: Jornada >12 h | C10: Alta | D10: 2026-08-24 | E10: PINEDA LARA, GERSON NICOLAS | F10: 17.55 | G10: Total diario Fixed superior a 12 horas. | H10: Revisar duplicidad o distribución de la jornada.
A11: Jul-Sep 4 | B11: Jornada >12 h | C11: Alta | D11: 2026-07-29 | E11: GARZON LOPEZ, SANTIAGO JOSE | F11: 14.25 | G11: Total diario Fixed superior a 12 horas. | H11: Revisar duplicidad o distribución de la jornada.
A12: Jul-Sep 4 | B12: Fin de semana | C12: Media | D12: 2026-08-23 | E12: SIERRA, JORGE | F12: 8 | G12: Horas Fixed registradas sábado o domingo. | H12: Confirmar autorización y realidad del trabajo.
A13: Jul-Sep 4 | B13: Fin de semana | C13: Media | D13: 2026-08-16 | E13: SIERRA, JORGE | F13: 8 | G13: Horas Fixed registradas sábado o domingo. | H13: Confirmar autorización y realidad del trabajo.
A14: Jul-Sep 4 | B14: Fin de semana | C14: Media | D14: 2026-08-08 | E14: SIERRA, JORGE | F14: 6 | G14: Horas Fixed registradas sábado o domingo. | H14: Confirmar autorización y realidad del trabajo.
A15: Jul-Sep 4 | B15: Fin de semana | C15: Media | D15: 2026-08-01 | E15: ALGARRA, NICOLAS | F15: 6 | G15: Horas Fixed registradas sábado o domingo. | H15: Confirmar autorización y realidad del trabajo.
A16: Jul-Sep 4 | B16: Fin de semana | C16: Media | D16: 2026-08-01 | E16: GARCIA FLOREZ, JUAN FERNANDO | F16: 3.5 | G16: Horas Fixed registradas sábado o domingo. | H16: Confirmar autorización y realidad del trabajo.
... A68: Jul-Sep 4 | B68: Carga contra plan 0% | C68: Alta | D68: Septiembre | E68: Tomas Carrillo Garcia | F68: 33 | G68: Registró horas Fixed aunque la planeación mensual es 0%. | H68: Validar imputación o actualizar planeación.

Sheet Alertas por linea
A1: Alertas de cumplimiento por línea
A2: Detalle de faltantes, desviaciones y cargas sin planeación para Fixed y RET. Auditoría/contratistas excluidas.
A4: Línea | B4: Equipo | C4: Persona | D4: Mes | E4: % planeado | F4: Esperado h | G4: Real h | H4: Desviación h | I4: Cumplimiento | J4: Estado
A5: Fixed
A6: Fixed
A7: Fixed
A8: RET
A9: Fixed
A10: RET
A11: Fixed
A12: Fixed
A13: Fixed
A14: Fixed
A15: Fixed
A16: Fixed
... A82: Fixed

Sheet Planeacion normalizada
A1: Planeación normalizada
A2: Primer porcentaje = implementación Fixed; segundo porcentaje = operación RET.
A4: Equipo | B4: Persona | C4: Mes | D4: Valor original | E4: % Fixed | F4: % RET | G4: % asignado | H4: % no asignado
A5: Los Dioses | B5: Gerson Nicolas Pineda Lara | C5: Julio | D5: 100%/0% | E5: 1 | F5: 0 | G5: =E5+F5 -> 1 | H5: =1-G5 -> 0
A6: Los Dioses | B6: Gerson Nicolas Pineda Lara | C6: Agosto | D6: 90% / 10% | E6: 0.9 | F6: 0.1 | G6: =E6+F6 -> 1 | H6: =1-G6 -> 0
A7: Los Dioses | B7: Gerson Nicolas Pineda Lara | C7: Septiembre | D7: 90% / 10% | E7: 0.9 | F7: 0.1 | G7: =E7+F7 -> 1 | H7: =1-G7 -> 0
A8: Los Dioses | B8: Diego Andres Saavedra Perez | C8: Julio | D8: 100%/0% | E8: 1 | F8: 0 | G8: =E8+F8 -> 1 | H8: =1-G8 -> 0
A9: Los Dioses | B9: Diego Andres Saavedra Perez | C9: Agosto | D9: 90% / 10% | E9: 0.9 | F9: 0.1 | G9: =E9+F9 -> 1 | H9: =1-G9 -> 0
A10: Los Dioses | B10: Diego Andres Saavedra Perez | C10: Septiembre | D10: 90% / 10% | E10: 0.9 | F10: 0.1 | G10: =E10+F10 -> 1 | H10: =1-G10 -> 0
A11: Los Dioses | B11: Harold Abdullah Lamphrey Munoz | C11: Julio | D11: 100%/0% | E11: 1 | F11: 0 | G11: =E11+F11 -> 1 | H11: =1-G11 -> 0
A12: Los Dioses | B12: Harold Abdullah Lamphrey Munoz | C12: Agosto | D12: 100%/0% | E12: 1 | F12: 0 | G12: =E12+F12 -> 1 | H12: =1-G12 -> 0
A13: Los Dioses | B13: Harold Abdullah Lamphrey Munoz | C13: Septiembre | D13: 100%/0% | E13: 1 | F13: 0 | G13: =E13+F13 -> 1 | H13: =1-G13 -> 0
A14: Anomalias | B14: Diana Patricia Aldana Moreno | C14: Julio | D14: 100%/0% | E14: 1 | F14: 0 | G14: =E14+F14 -> 1 | H14: =1-G14 -> 0
A15: Anomalias | B15: Diana Patricia Aldana Moreno | C15: Agosto | D15: 50%/0 | E15: 0.5 | F15: 0 | G15: =E15+F15 -> 0.5 | H15: =1-G15 -> 0.5
A16: Anomalias | B16: Diana Patricia Aldana Moreno | C16: Septiembre | D16: 0 | E16: 0 | F16: 0 | G16: =E16+F16 -> 0 | H16: =1-G16 -> 1
... A106: Contratistas | B106: Leonardo Beltran | C106: Septiembre | D106: 0 | E106: 0 | F106: 0 | G106: =E106+F106 -> 0 | H106: =1-G106 -> 1

Sheet Mapeo nombres
A1: Mapeo de personas
A2: Correspondencia aplicada entre nombres de planeación y nombres de OpenAir.
A4: Persona planeada | B4: Nombre OpenAir | C4: Confianza | D4: Excluido | E4: Equipo | F4: Comentario
A5: Gerson Nicolas Pineda Lara | B5: PINEDA LARA, GERSON NICOLAS | C5: 1 | D5: No | E5: Los Dioses
A6: Diego Andres Saavedra Perez | B6: SAAVEDRA PEREZ, DIEGO ANDRES | C6: 1 | D6: No | E6: Los Dioses
A7: Harold Abdullah Lamphrey Munoz | B7: LAMPHREY MUÑOZ, HAROLD ABDULLAH | C7: 1 | D7: No | E7: Los Dioses
A8: Diana Patricia Aldana Moreno | B8: ALDANA MORENO, DIANA | C8: 0.80851064 | D8: No | E8: Anomalias
A9: Kevin Camilo Rincon Bohorquez | B9: RINCON BOHORQUEZ, KEVIN CAMILO | C9: 1 | D9: No | E9: Medicamentos + Notificacion
A10: Angela Maria Santos Hernandez | B10: SANTOS, ANGELA | C10: 1 | D10: No | E10: Medicamentos + Notificacion
A11: Cristian David Casas Diaz | B11: CASAS, CRISTIAN | C11: 1 | D11: No | E11: Medicamentos + Notificacion
A12: Harold Burbano | B12: BURBANO, HAROLD | C12: 1 | D12: No | E12: Medicamentos + Notificacion
A13: Daniel Castillo Giraldo | B13: CASTILLO GIRALDO, DANIEL | C13: 1 | D13: No | E13: Infraestructura
A14: Simon Calderon Lopez | B14: CALDERON, SIMON | C14: 0.82352941 | D14: No | E14: Infraestructura
A15: Jorge Humberto Sierra Laiton | B15: SIERRA, JORGE | C15: 1 | D15: No | E15: Infraestructura
A16: Javier Steven Barrera Toro | B16: BARRERA, JAVIER | C16: 1 | D16: No | E16: Infraestructura
... A28: Johan David Espitia Pachon | B28: ESPITIA PACHON, JOHAN DAVID | C28: 1 | D28: No | E28: SGA
A29: Franklin Julian Gonzalez Perez | B29: GONZALEZ, FRANKLIN | C29: 0.72340426 | D29: No | E29: SGA | F29: Revisar mapeo
A30: Valentina Villegas Correal | B30: VILLEGAS CORREAL, VALENTINA | C30: 1 | D30: No | E30: SGA
A31: Maryith Viviana Garzon Silva | B31: GARZON SILVA, MARYITH VIVIANA | C31: 1 | D31: No | E31: Consultas, Estancias y Dashboard
A32: Luis Antonio Zuluaga Ramirez | B32: ZULUAGA, LUIS | C32: 1 | D32: No | E32: Consultas, Estancias y Dashboard
A33: Daniel Santiago Avila Medina | B33: AVILA, DANIEL | C33: 1 | D33: No | E33: Consultas, Estancias y Dashboard
A34: Etelvina Mejia | C34: 0.45 | D34: Sí | E34: Contratistas | F34: Auditoría/contratista: no se espera carga
A35: Myriam Pulido | C35: 0.60869565 | D35: Sí | E35: Contratistas | F35: Auditoría/contratista: no se espera carga
A36: Claudia Quintero | C36: 0.48275862 | D36: Sí | E36: Contratistas | F36: Auditoría/contratista: no se espera carga
A37: Martha Ardila | C37: 0.51851852 | D37: Sí | E37: Contratistas | F37: Auditoría/contratista: no se espera carga
A38: Leonardo Beltran | C38: 0.56 | D38: Sí | E38: Contratistas | F38: Auditoría/contratista: no se espera carga

Sheet Fuentes y supuestos
A1: Fuentes, alcance y supuestos
A2: Trazabilidad del análisis y criterios aplicados.
A4: Tipo | B4: Elemento | C4: Detalle | D4: Uso | E4: Observación
A5: Fuente | B5: Planeación | C5: C:\Users\Juana Chicacausa\OneDrive - Blend 360\Escritorio\Git\adr-project-control-P2457\Control CET\Input\Planeación equipo 20260803 (1).xlsx | D5: Porcentajes mensuales Fixed/RET | E5: Julio a diciembre
A6: Fuente | B6: Fixed | C6: C:\Users\Juana Chicacausa\OneDrive - Blend 360\Escritorio\Git\adr-project-control-P2457\Control CET\Input\Solo Hora Fixed 20260904.csv | D6: Horas de implementación | E6: Fuente principal de Fixed
A7: Fuente | B7: RET | C7: C:\Users\Juana Chicacausa\OneDrive - Blend 360\Escritorio\Git\adr-operation-project-control-P2847\Control CET\Input\20260804 Horas OpenAir.csv | D7: Horas reales de operación RET | E7: Única fuente usada para RET real h; corte 2026-09-04
A8: Supuesto | C8: Corte del análisis: 2026-09-04, inferido del nombre del archivo; registros posteriores se excluyen y se reportan como futuros.
A9: Supuesto | C9: Capacidad: lunes a jueves 8,5 horas y viernes 8 horas (42 horas semanales); se descuentan festivos nacionales de Colombia.
A10: Supuesto | C10: Para septiembre, la capacidad esperada se prorratea del 1 al 4 de septiembre.
A11: Supuesto | B11: RET | C11: C:\Users\Juana Chicacausa\OneDrive - Blend 360\Escritorio\Git\adr-operation-project-control-P2847\Control CET\Input\20260804 Horas OpenAir.csv | D11: Horas reales de operación RET | E11: Única fuente usada para RET real h; corte 2026-09-04
A12: Supuesto | C12: La proporción real es Fixed/(Fixed+RET). Cuando no hay horas en ambos proyectos, queda vacía.
A13: Supuesto | C13: Las personas bajo la sección Contratistas se excluyen de alertas de ausencia por instrucción del usuario sobre auditoras que no registran horas.
A14: Supuesto | C14: Umbral de desviación: más de 10% de las horas esperadas, con mínimo de 8 horas; o más de 10 puntos porcentuales en la mezcla Fixed/RET.
A15: Limitación | B15: Capacidad | C15: Se descontaron festivos nacionales. No se descontaron vacaciones, incapacidades, licencias, permisos ni PTO. | E15: Puede explicar parte de las desviaciones.
A16: Control | B16: Conciliación | C16: 9 registros están solo en Solo Hora Fixed y 0 solo en Horas ADRES. | E16: Revisar filtros de extracción.
A17: Cálculo
A18: Cálculo | B18: Análisis ambas líneas | C18: Se evalúan horas, cumplimiento y mezcla Fixed/RET; también el total conjunto y la capacidad no asignada. | D18: Resumen y Cumplimiento | E18: Los excesos de una línea no compensan alertas de la otra.

Sheet Calendario laboral
A1: Calendario laboral Colombia 2026
A2: Jornada: lunes a jueves 8,5 h; viernes 8 h. Festivos nacionales descontados. Corte: 2026-09-04.
A4: Fecha | B4: Día | C4: Mes | D4: Es festivo | E4: Festivo | F4: Horas programadas | G4: Horas disponibles
A5: 46204 | B5: miércoles | C5: Julio | D5: No | F5: 8.5 | G5: 8.5
A6: 46205 | B6: jueves | C6: Julio | D6: No | F6: 8.5 | G6: 8.5
A7: 46206 | B7: viernes | C7: Julio | D7: No | F7: 8 | G7: 8
A8: 46207 | B8: sábado | C8: Julio | D8: No | F8: 0 | G8: 0
A9: 46208 | B9: domingo | C9: Julio | D9: No | F9: 0 | G9: 0
A10: 46209 | B10: lunes | C10: Julio | D10: No | F10: 8.5 | G10: 8.5
A11: 46210 | B11: martes | C11: Julio | D11: No | F11: 8.5 | G11: 8.5
A12: 46211 | B12: miércoles | C12: Julio | D12: No | F12: 8.5 | G12: 8.5
A13: 46212 | B13: jueves | C13: Julio | D13: No | F13: 8.5 | G13: 8.5
A14: 46213 | B14: viernes | C14: Julio | D14: No | F14: 8 | G14: 8
A15: 46214 | B15: sábado | C15: Julio | D15: No | F15: 0 | G15: 0
A16: 46215 | B16: domingo | C16: Julio | D16: No | F16: 0 | G16: 0
A17: 46216 | B17: lunes | C17: Julio | D17: Sí | E17: Nuestra Señora del Rosario de Chiquinquirá (trasladado) | F17: 8.5 | G17: 0
A18: 46217 | B18: martes | C18: Julio | D18: No | F18: 8.5 | G18: 8.5
A19: 46218 | B19: miércoles | C19: Julio | D19: No | F19: 8.5 | G19: 8.5
A20: 46219 | B20: jueves | C20: Julio | D20: No | F20: 8.5 | G20: 8.5
A21: 46220 | B21: viernes | C21: Julio | D21: No | F21: 8 | G21: 8
A22: 46221 | B22: sábado | C22: Julio | D22: No | F22: 0 | G22: 0
A23: 46222 | B23: domingo | C23: Julio | D23: No | F23: 0 | G23: 0
A24: 46223 | B24: lunes | C24: Julio | D24: Sí | E24: Día de la Independencia | F24: 8.5 | G24: 0
A25: 46224 | B25: martes | C25: Julio | D25: No | F25: 8.5 | G25: 8.5
A26: 46225 | B26: miércoles | C26: Julio | D26: No | F26: 8.5 | G26: 8.5
A27: 46226 | B27: jueves | C27: Julio | D27: No | F27: 8.5 | G27: 8.5
A28: 46227 | B28: viernes | C28: Julio | D28: No | F28: 8 | G28: 8
A29: 46228 | B29: sábado | C29: Julio | D29: No | F29: 0 | G29: 0
A30: 46229 | B30: domingo | C30: Julio | D30: No | F30: 0 | G30: 0
A31: 46230 | B31: lunes | C31: Julio | D31: No | F31: 8.5 | G31: 8.5
A32: 46231 | B32: martes | C32: Julio | D32: No | F32: 8.5 | G32: 8.5
A33: 46232 | B33: miércoles | C33: Julio | D33: No | F33: 8.5 | G33: 8.5
A34: 46233 | B34: jueves | C34: Julio | D34: No | F34: 8.5 | G34: 8.5
A35: 46234 | B35: viernes | C35: Julio | D35: No | F35: 8 | G35: 8
A36: 46235 | B36: sábado | C36: Agosto | D36: No | F36: 0 | G36: 0
... A41: 46240 | B41: jueves | C41: Agosto | D41: No | F41: 8.5 | G41: 8.5
A42: 46241 | B42: viernes | C42: Agosto | D42: Sí | E42: Batalla de Boyacá | F42: 8 | G42: 0
A43: 46242 | B43: sábado | C43: Agosto | D43: No | F43: 0 | G43: 0
A44: 46243 | B44: domingo | C44: Agosto | D44: No | F44: 0 | G44: 0
A45: 46244 | B45: lunes | C45: Agosto | D45: No | F45: 8.5 | G45: 8.5
...

Sheet RET OpenAir fuente
A1: Fuente de horas RET - OpenAir Operación
A2: Fuente exclusiva para RET real h. Los registros fuera de julio a 2026-09-04 se conservan, pero no se incluyen.
A4: Fecha | B4: Usuario | C4: Proyecto | D4: Horas | E4: Mes | F4: Incluido en análisis
A5: 46276 | B5: ZAMBRANO, JUAN | C5: CO - Adres - Operación Auditoria Cuentas Medicas - Ret | D5: 0.5 | E5: Septiembre | F5: No
A6: 46275 | B6: ZAMBRANO, JUAN | C6: CO - Adres - Operación Auditoria Cuentas Medicas - Ret | D6: 0.5 | E6: Septiembre | F6: No
A7: 46274 | B7: ZAMBRANO, JUAN | C7: CO - Adres - Operación Auditoria Cuentas Medicas - Ret | D7: 0.5 | E7: Septiembre | F7: No
A8: 46273 | B8: ZAMBRANO, JUAN | C8: CO - Adres - Operación Auditoria Cuentas Medicas - Ret | D8: 0.5 | E8: Septiembre | F8: No
A9: 46272 | B9: ZAMBRANO, JUAN | C9: CO - Adres - Operación Auditoria Cuentas Medicas - Ret | D9: 0.5 | E9: Septiembre | F9: No
A10: 46269 | B10: PINEDA LARA, GERSON NICOLAS | C10: CO - Adres - Operación Auditoria Cuentas Medicas - Ret | D10: 0.8 | E10: Septiembre | F10: Sí
A11: 46269 | B11: SANCHEZ YAÑEZ, NICOLAS DAVID | C11: CO - Adres - Operación Auditoria Cuentas Medicas - Ret | D11: 8 | E11: Septiembre | F11: Sí
A12: 46269 | B12: ZAMBRANO, JUAN | C12: CO - Adres - Operación Auditoria Cuentas Medicas - Ret | D12: 0.5 | E12: Septiembre | F12: Sí
A13: 46269 | B13: ANGEL VAHOS, CRISTIAN PAUL | C13: CO - Adres - Operación Auditoria Cuentas Medicas - Ret | D13: 8 | E13: Septiembre | F13: Sí
A14: 46268 | B14: PINEDA LARA, GERSON NICOLAS | C14: CO - Adres - Operación Auditoria Cuentas Medicas - Ret | D14: 0.85 | E14: Septiembre | F14: Sí
A15: 46268 | B15: SANCHEZ YAÑEZ, NICOLAS DAVID | C15: CO - Adres - Operación Auditoria Cuentas Medicas - Ret | D15: 8.5 | E15: Septiembre | F15: Sí
A16: 46268 | B16: ZAMBRANO, JUAN | C16: CO - Adres - Operación Auditoria Cuentas Medicas - Ret | D16: 0.5 | E16: Septiembre | F16: Sí
... A191: 46204 | B191: ZAMBRANO, JUAN | C191: CO - Adres - Operación Auditoria Cuentas Medicas - Ret | D191: 0.5 | E191: Julio | F191: Sí
A192: 46203 | B192: LALLE MONTAÑA, DANIELA | C192: CO - Adres - Operación Auditoria Cuentas Medicas - Ret | D192: 7 | F192: No
A193: 46203 | B193: RODRIGUEZ RUBIO, SERGIO | C193: CO - Adres - Operación Auditoria Cuentas Medicas - Ret | D193: 7 | F193: No
A194: 46199 | B194: ZAMBRANO, JUAN | C194: CO - Adres - Operación Auditoria Cuentas Medicas - Ret | D194: 0.5 | F194: No
A195: 46199 | B195: LALLE MONTAÑA, DANIELA | C195: CO - Adres - Operación Auditoria Cuentas Medicas - Ret | D195: 3 | F195: No
A196: 46199 | B196: ROJAS CHARRY, DIANA CLEMENCIA | C196: CO - Adres - Operación Auditoria Cuentas Medicas - Ret | D196: 2 | F196: No
A197: 46198 | B197: ZAMBRANO, JUAN | C197: CO - Adres - Operación Auditoria Cuentas Medicas - Ret | D197: 0.5 | F197: No
A198: 46198 | B198: BERNAL, HERNANDO | C198: CO - Adres - Operación Auditoria Cuentas Medicas - Ret | D198: 2 | F198: No
A199: 46198 | B199: LALLE MONTAÑA, DANIELA | C199: CO - Adres - Operación Auditoria Cuentas Medicas - Ret | D199: 7.5 | F199: No
A200: 46198 | B200: RODRIGUEZ RUBIO, SERGIO | C200: CO - Adres - Operación Auditoria Cuentas Medicas - Ret | D200: 4 | F200: No
A201: 46198 | B201: ROJAS CHARRY, DIANA CLEMENCIA | C201: CO - Adres - Operación Auditoria Cuentas Medicas - Ret | D201: 4 | F201: No
A202: 46198 | B202: CASTILLO GIRALDO, DANIEL | C202: CO - Adres - Operación Auditoria Cuentas Medicas - Ret | D202: 2 | F202: No
A203: 46197 | B203: ZAMBRANO, JUAN | C203: CO - Adres - Operación Auditoria Cuentas Medicas - Ret | D203: 0.5 | F203: No
... A320: 46119 | B320: ROJAS CHARRY, DIANA CLEMENCIA | C320: CO - Adres - Operación Auditoria Cuentas Medicas - Ret | D320: 4 | F320: No
